Workbook
Name Slicer_Content_Category: #N/A
Name Slicer_Content_Type: #N/A
Name Slicer_Platform: #N/A
Name Slicer_Post_day: #N/A
Name Slicer_Post_Month: #N/A
Name Slicer_Post_Type: #N/A
Name Slicer_Region: #N/A
Name Slicer_Time_Slot: #N/A

Sheet Old_Data
A1: Post_ID | B1: Platform | C1: Content_Type | D1: Content_Category | E1: Post_Type | F1: Region | G1: Longitude | H1: Latitude | I1: Engagement | J1: Views | K1: Likes | L1: Shares | M1: Comments | N1: Engagement_Rate | O1: Impressions | P1: Video_Views | Q1: Live_Stream_Views | R1: Clicks | S1: Click_Through_Rate | T1: Main_Hashtag | U1: Post_Date | V1: Post_day | W1: Post_Month | X1: Post_Hour | Y1: Time_Slot | Z1: Engagement_Level
A2: Post_1 | B2: TikTok | C2: Organic | D2: Product Promotion | E2: Video | F2: UK | G2: -3.436 | H2: 55.3781 | I2: 54510 | J2: 599342 | K2: 125741 | L2: 35920 | M2: 15727 | N2: 0.09095057 | O2: 677975 | P2: 465645 | Q2: 0 | R2: 16813 | S2: 0.0248 | T2: #FeatureHighlight | U2: 45365 | V2: =TEXT(U2,"DDDD") -> Thursday | W2: =TEXT(U2,"MMMM") -> March | X2: 15 | Y2: =IF(X2<6,"NIght",IF(X2<12,"Morning",IF(X2<18,"Afternoon","Evening"))) -> Afternoon | Z2: Low
A3: Post_2 | B3: Instagram | C3: Organic | D3: Product Promotion | E3: Video | F3: India | G3: 78.9629 | H3: 20.5937 | I3: 259440 | J3: 1896301 | K3: 206151 | L3: 139015 | M3: 83521 | N3: 0.13681396 | O3: 2354474 | P3: 1896301 | Q3: 0 | T3: #ProductDemo | U3: 45406 | V3: =TEXT(U3,"DDDD") -> Wednesday | W3: =TEXT(U3,"MMMM") -> April | X3: 12 | Y3: =IF(X3<6,"NIght",IF(X3<12,"Morning",IF(X3<18,"Afternoon","Evening"))) -> Afternoon | Z3: Medium
A4: Post_3 | B4: X.com | C4: Organic | D4: Entertainment | E4: Text | F4: Brazil | G4: -51.9253 | H4: -14.235 | I4: 14182 | J4: 253052 | K4: 32206 | L4: 9912 | M4: 8140 | N4: 0.056045015 | O4: 304915 | P4: 0 | Q4: 0 | T4: #MemeMonday | U4: 45627 | V4: =TEXT(U4,"DDDD") -> Sunday | W4: =TEXT(U4,"MMMM") -> December | X4: 10 | Y4: =IF(X4<6,"NIght",IF(X4<12,"Morning",IF(X4<18,"Afternoon","Evening"))) -> Morning | Z4: Low
A5: Post_4 | B5: Instagram | C5: Organic | D5: Entertainment | E5: Carousel | F5: Australia | G5: 133.7751 | H5: -25.2744 | I5: 49137 | J5: 735640 | K5: 121227 | L5: 32781 | M5: 32716 | N5: 0.066795973 | O5: 829727 | P5: 0 | Q5: 0 | T5: #JustForFun | U5: 45480 | V5: =TEXT(U5,"DDDD") -> Sunday | W5: =TEXT(U5,"MMMM") -> July | X5: 12 | Y5: =IF(X5<6,"NIght",IF(X5<12,"Morning",IF(X5<18,"Afternoon","Evening"))) -> Afternoon | Z5: Low
A6: Post_5 | B6: TikTok | C6: Organic | D6: Educational | E6: Video | F6: Brazil | G6: -51.9253 | H6: -14.235 | I6: 20832 | J6: 77358 | K6: 13027 | L6: 5357 | M6: 2165 | N6: 0.26930187 | O6: 93049 | P6: 72707 | Q6: 0 | R6: 1944 | S6: 0.0209 | T6: #CaseStudy2025 | U6: 45301 | V6: =TEXT(U6,"DDDD") -> Wednesday | W6: =TEXT(U6,"MMMM") -> January | X6: 11 | Y6: =IF(X6<6,"NIght",IF(X6<12,"Morning",IF(X6<18,"Afternoon","Evening"))) -> Morning | Z6: High
A7: Post_6 | B7: LinkedIn | C7: Organic | D7: Customer Story | E7: Image | F7: Australia | G7: 133.7751 | H7: -25.2744 | I7: 47292 | J7: 217539 | K7: 41084 | L7: 7031 | M7: 9637 | N7: 0.21739867 | O7: 246712 | P7: 0 | Q7: 0 | T7: #SuccessStory | U7: 45327 | V7: =TEXT(U7,"DDDD") -> Monday | W7: =TEXT(U7,"MMMM") -> February | X7: 9 | Y7: =IF(X7<6,"NIght",IF(X7<12,"Morning",IF(X7<18,"Afternoon","Evening"))) -> Morning | Z7: High
A8: Post_7 | B8: YouTube | C8: Organic | D8: Customer Story | E8: Video | F8: Japan | G8: 138.2529 | H8: 36.2048 | I8: 44036 | J8: 189936 | K8: 38487 | L8: 9878 | M8: 4725 | N8: 0.23184858 | O8: 227739 | P8: 178450 | Q8: 0 | T8: #CustomerStory | U8: 45417 | V8: =TEXT(U8,"DDDD") -> Sunday | W8: =TEXT(U8,"MMMM") -> May | X8: 12 | Y8: =IF(X8<6,"NIght",IF(X8<12,"Morning",IF(X8<18,"Afternoon","Evening"))) -> Afternoon | Z8: High
A9: Post_8 | B9: YouTube | C9: Organic | D9: Customer Story | E9: Video | F9: UK | G9: -3.436 | H9: 55.3781 | I9: 325640 | J9: 1781229 | K9: 187310 | L9: 134422 | M9: 54062 | N9: 0.18281798 | O9: 2195372 | P9: 1781229 | Q9: 0 | T9: #CustomerStory | U9: 45374 | V9: =TEXT(U9,"DDDD") -> Saturday | W9: =TEXT(U9,"MMMM") -> March | X9: 15 | Y9: =IF(X9<6,"NIght",IF(X9<12,"Morning",IF(X9<18,"Afternoon","Evening"))) -> Afternoon | Z9: Medium
A10: Post_9 | B10: X.com | C10: Organic | D10: Product Promotion | E10: Text | F10: India | G10: 78.9629 | H10: 20.5937 | I10: 38084 | J10: 270886 | K10: 49303 | L10: 10630 | M10: 15923 | N10: 0.14059304 | O10: 339969 | P10: 0 | Q10: 0 | T10: #FeatureHighlight | U10: 45776 | V10: =TEXT(U10,"DDDD") -> Tuesday | W10: =TEXT(U10,"MMMM") -> April | X10: 16 | Y10: =IF(X10<6,"NIght",IF(X10<12,"Morning",IF(X10<18,"Afternoon","Evening"))) -> Afternoon | Z10: Medium
A11: Post_10 | B11: TikTok | C11: Organic | D11: Product Promotion | E11: Video | F11: India | G11: 78.9629 | H11: 20.5937 | I11: 76170 | J11: 530247 | K11: 124196 | L11: 31759 | M11: 30157 | N11: 0.14365078 | O11: 592656 | P11: 530247 | Q11: 0 | R11: 8949 | S11: 0.0151 | T11: #ProductDemo | U11: 45704 | V11: =TEXT(U11,"DDDD") -> Sunday | W11: =TEXT(U11,"MMMM") -> February | X11: 15 | Y11: =IF(X11<6,"NIght",IF(X11<12,"Morning",IF(X11<18,"Afternoon","Evening"))) -> Afternoon | Z11: Medium
A12: Post_11 | B12: Instagram | C12: Organic | D12: Event / Webinar | E12: Live Stream | F12: Germany | G12: 10.4515 | H12: 51.1657 | I12: 26520 | J12: 149091 | K12: 20977 | L12: 10650 | M12: 5109 | N12: 0.17788131 | O12: 172377 | P12: 0 | Q12: 317078 | T12: #EventRecap | U12: 45593 | V12: =TEXT(U12,"DDDD") -> Monday | W12: =TEXT(U12,"MMMM") -> October | X12: 10 | Y12: =IF(X12<6,"NIght",IF(X12<12,"Morning",IF(X12<18,"Afternoon","Evening"))) -> Morning | Z12: Medium
A13: Post_12 | B13: X.com | C13: Organic | D13: Educational | E13: Text | F13: Australia | G13: 133.7751 | H13: -25.2744 | I13: 22233 | J13: 91670 | K13: 11104 | L13: 6426 | M13: 2106 | N13: 0.24253383 | O13: 118930 | P13: 0 | Q13: 0 | T13: #SuccessStory | U13: 45405 | V13: =TEXT(U13,"DDDD") -> Tuesday | W13: =TEXT(U13,"MMMM") -> April | X13: 15 | Y13: =IF(X13<6,"NIght",IF(X13<12,"Morning",IF(X13<18,"Afternoon","Evening"))) -> Afternoon | Z13: High
A14: Post_13 | B14: YouTube | C14: Sponsored | D14: Educational | E14: Video | F14: Canada | G14: -106.3468 | H14: 56.1304 | I14: 226309 | J14: 1492308 | K14: 150466 | L14: 105615 | M14: 72040 | N14: 0.15165093 | O14: 1859119 | P14: 1492308 | Q14: 0 | T14: #CustomerStory | U14: 45695 | V14: =TEXT(U14,"DDDD") -> Friday | W14: =TEXT(U14,"MMMM") -> February | X14: 9 | Y14: =IF(X14<6,"NIght",IF(X14<12,"Morning",IF(X14<18,"Afternoon","Evening"))) -> Morning | Z14: Medium
A15: Post_14 | B15: YouTube | C15: Organic | D15: Educational | E15: Video | F15: Japan | G15: 138.2529 | H15: 36.2048 | I15: 71888 | J15: 311167 | K15: 67115 | L15: 10487 | M15: 10685 | N15: 0.23102875 | O15: 349494 | P15: 281653 | Q15: 0 | T15: #CustomerStory | U15: 45769 | V15: =TEXT(U15,"DDDD") -> Tuesday | W15: =TEXT(U15,"MMMM") -> April | X15: 19 | Y15: =IF(X15<6,"NIght",IF(X15<12,"Morning",IF(X15<18,"Afternoon","Evening"))) -> Evening | Z15: High
A16: Post_15 | B16: X.com | C16: Organic | D16: Entertainment | E16: Text | F16: Germany | G16: 10.4515 | H16: 51.1657 | I16: 53010 | J16: 566252 | K16: 84730 | L16: 18787 | M16: 18368 | N16: 0.093616415 | O16: 659704 | P16: 0 | Q16: 0 | T16: #FunContent | U16: 45428 | V16: =TEXT(U16,"DDDD") -> Thursday | W16: =TEXT(U16,"MMMM") -> May | X16: 15 | Y16: =IF(X16<6,"NIght",IF(X16<12,"Morning",IF(X16<18,"Afternoon","Evening"))) -> Afternoon | Z16: Low
A17: Post_16 | B17: YouTube | C17: Organic | D17: Product Promotion | E17: Live Stream | F17: Canada | G17: -106.3468 | H17: 56.1304 | I17: 30263 | J17: 347554 | K17: 72792 | L17: 21505 | M17: 19285 | N17: 0.087074837 | O17: 415133 | P17: 0 | Q17: 679391 | T17: #ProductDemo | U17: 45664 | V17: =TEXT(U17,"DDDD") -> Tuesday | W17: =TEXT(U17,"MMMM") -> January | X17: 15 | Y17: =IF(X17<6,"NIght",IF(X17<12,"Morning",IF(X17<18,"Afternoon","Evening"))) -> Afternoon | Z17: Low
A18: Post_17 | B18: X.com | C18: Organic | D18: Educational | E18: Image | F18: UK | G18: -3.436 | H18: 55.3781 | I18: 58337 | J18: 347296 | K18: 63968 | L18: 23806 | M18: 13805 | N18: 0.16797716 | O18: 418334 | P18: 0 | Q18: 0 | T18: #SuccessStory | U18: 45627 | V18: =TEXT(U18,"DDDD") -> Sunday | W18: =TEXT(U18,"MMMM") -> December | X18: 11 | Y18: =IF(X18<6,"NIght",IF(X18<12,"Morning",IF(X18<18,"Afternoon","Evening"))) -> Morning | Z18: Medium
A19: Post_18 | B19: TikTok | C19: Sponsored | D19: Educational | E19: Video | F19: UK | G19: -3.436 | H19: 55.3781 | I19: 510212 | J19: 2596696 | K19: 426198 | L19: 81201 | M19: 63140 | N19: 0.19648537 | O19: 2872688 | P19: 2596696 | Q19: 0 | R19: 31312 | S19: 0.0109 | T19: #CustomerStory | U19: 45454 | V19: =TEXT(U19,"DDDD") -> Tuesday | W19: =TEXT(U19,"MMMM") -> June | X19: 10 | Y19: =IF(X19<6,"NIght",IF(X19<12,"Morning",IF(X19<18,"Afternoon","Evening"))) -> Morning | Z19: Medium
A20: Post_19 | B20: TikTok | C20: Organic | D20: Product Promotion | E20: Video | F20: USA | G20: -95.7129 | H20: 37.0902 | I20: 29522 | J20: 216249 | K20: 38121 | L20: 16300 | M20: 6481 | N20: 0.13652218 | O20: 255622 | P20: 3466 | Q20: 0 | R20: 3246 | S20: 0.0127 | T20: #FeatureHighlight | U20: 45307 | V20: =TEXT(U20,"DDDD") -> Tuesday | W20: =TEXT(U20,"MMMM") -> January | X20: 11 | Y20: =IF(X20<6,"NIght",IF(X20<12,"Morning",IF(X20<18,"Afternoon","Evening"))) -> Morning | Z20: Medium
A21: Post_20 | B21: YouTube | C21: Organic | D21: Educational | E21: Video | F21: UK | G21: -3.436 | H21: 55.3781 | I21: 58869 | J21: 354249 | K21: 75572 | L21: 14680 | M21: 8175 | N21: 0.16618209 | O21: 410202 | P21: 308035 | Q21: 0 | T21: #CustomerStory | U21: 45579 | V21: =TEXT(U21,"DDDD") -> Monday | W21: =TEXT(U21,"MMMM") -> October | X21: 12 | Y21: =IF(X21<6,"NIght",IF(X21<12,"Morning",IF(X21<18,"Afternoon","Evening"))) -> Afternoon | Z21: Medium
A22: Post_21 | B22: X.com | C22: Organic | D22: Product Promotion | E22: Video | F22: Brazil | G22: -51.9253 | H22: -14.235 | I22: 340149 | J22: 2376086 | K22: 548208 | L22: 166762 | M22: 65253 | N22: 0.14315551 | O22: 3037853 | P22: 2376086 | Q22: 0 | T22: #ProductDemo | U22: 45460 | V22: =TEXT(U22,"DDDD") -> Monday | W22: =TEXT(U22,"MMMM") -> June | X22: 17 | Y22: =IF(X22<6,"NIght",IF(X22<12,"Morning",IF(X22<18,"Afternoon","Evening"))) -> Afternoon | Z22: Medium
A23: Post_22 | B23: TikTok | C23: Organic | D23: Product Promotion | E23: Live Stream | F23: USA | G23: -95.7129 | H23: 37.0902 | I23: 49757 | J23: 365818 | K23: 66176 | L23: 25743 | M23: 20428 | N23: 0.13601663 | O23: 425666 | P23: 0 | Q23: 77512 | R23: 4937 | S23: 0.0116 | T23: #FeatureHighlight | U23: 45683 | V23: =TEXT(U23,"DDDD") -> Sunday | W23: =TEXT(U23,"MMMM") -> January | X23: 15 | Y23: =IF(X23<6,"NIght",IF(X23<12,"Morning",IF(X23<18,"Afternoon","Evening"))) -> Afternoon | Z23: Medium
A24: Post_23 | B24: YouTube | C24: Organic | D24: Product Promotion | E24: Video | F24: Brazil | G24: -51.9253 | H24: -14.235 | I24: 197894 | J24: 1705918 | K24: 379911 | L24: 124594 | M24: 34592 | N24: 0.1160048 | O24: 2050768 | P24: 1705918 | Q24: 0 | T24: #ProductDemo | U24: 45610 | V24: =TEXT(U24,"DDDD") -> Thursday | W24: =TEXT(U24,"MMMM") -> November | X24: 19 | Y24: =IF(X24<6,"NIght",IF(X24<12,"Morning",IF(X24<18,"Afternoon","Evening"))) -> Evening | Z24: Medium
A25: Post_24 | B25: X.com | C25: Organic | D25: Product Promotion | E25: Video | F25: Japan | G25: 138.2529 | H25: 36.2048 | I25: 113610 | J25: 902363 | K25: 146734 | L25: 37091 | M25: 22373 | N25: 0.12590344 | O25: 1053529 | P25: 902363 | Q25: 0 | T25: #ProductDemo | U25: 45515 | V25: =TEXT(U25,"DDDD") -> Sunday | W25: =TEXT(U25,"MMMM") -> August | X25: 11 | Y25: =IF(X25<6,"NIght",IF(X25<12,"Morning",IF(X25<18,"Afternoon","Evening"))) -> Morning | Z25: Medium
A26: Post_25 | B26: YouTube | C26: Organic | D26: Educational | E26: Video | F26: Germany | G26: 10.4515 | H26: 51.1657 | I26: 58395 | J26: 233871 | K26: 41586 | L26: 15236 | M26: 8079 | N26: 0.24969113 | O26: 302712 | P26: 204799 | Q26: 0 | T26: #CustomerStory | U26: 45534 | V26: =TEXT(U26,"DDDD") -> Friday | W26: =TEXT(U26,"MMMM") -> August | X26: 12 | Y26: =IF(X26<6,"NIght",IF(X26<12,"Morning",IF(X26<18,"Afternoon","Evening"))) -> Afternoon | Z26: High
A27: Post_26 | B27: YouTube | C27: Organic | D27: Event / Webinar | E27: Live Stream | F27: Brazil | G27: -51.9253 | H27: -14.235 | I27: 42412 | J27: 290405 | K27: 70965 | L27: 12368 | M27: 11584 | N27: 0.14604667 | O27: 336920 | P27: 0 | Q27: 927260 | T27: #WebinarReplay | U27: 45434 | V27: =TEXT(U27,"DDDD") -> Wednesday | W27: =TEXT(U27,"MMMM") -> May | X27: 10 | Y27: =IF(X27<6,"NIght",IF(X27<12,"Morning",IF(X27<18,"Afternoon","Evening"))) -> Morning | Z27: Medium
A28: Post_27 | B28: Instagram | C28: Organic | D28: Product Promotion | E28: Video | F28: India | G28: 78.9629 | H28: 20.5937 | I28: 250854 | J28: 2076760 | K28: 364267 | L28: 67648 | M28: 64682 | N28: 0.12079132 | O28: 2661686 | P28: 2076760 | Q28: 0 | T28: #ProductDemo | U28: 45470 | V28: =TEXT(U28,"DDDD") -> Thursday | W28: =TEXT(U28,"MMMM") -> June | X28: 17 | Y28: =IF(X28<6,"NIght",IF(X28<12,"Morning",IF(X28<18,"Afternoon","Evening"))) -> Afternoon | Z28: Medium
A29: Post_28 | B29: YouTube | C29: Organic | D29: Entertainment | E29: Video | F29: Canada | G29: -106.3468 | H29: 56.1304 | I29: 35665 | J29: 413478 | K29: 56205 | L29: 15399 | M29: 16364 | N29: 0.086256793 | O29: 536334 | P29: 397501 | Q29: 0 | T29: #TrendingNow | U29: 45554 | V29: =TEXT(U29,"DDDD") -> Thursday | W29: =TEXT(U29,"MMMM") -> September | X29: 15 | Y29: =IF(X29<6,"NIght",IF(X29<12,"Morning",IF(X29<18,"Afternoon","Evening"))) -> Afternoon | Z29: Low
A30: Post_29 | B30: Instagram | C30: Organic | D30: Event / Webinar | E30: Live Stream | F30: Canada | G30: -106.3468 | H30: 56.1304 | I30: 35525 | J30: 326729 | K30: 69999 | L30: 13684 | M30: 16051 | N30: 0.10873047 | O30: 383434 | P30: 0 | Q30: 352922 | T30: #EventRecap | U30: 45674 | V30: =TEXT(U30,"DDDD") -> Friday | W30: =TEXT(U30,"MMMM") -> January | X30: 12 | Y30: =IF(X30<6,"NIght",IF(X30<12,"Morning",IF(X30<18,"Afternoon","Evening"))) -> Afternoon | Z30: Medium
A31: Post_30 | B31: YouTube | C31: Organic | D31: Event / Webinar | E31: Live Stream | F31: Japan | G31: 138.2529 | H31: 36.2048 | I31: 182898 | J31: 1137655 | K31: 221876 | L31: 64605 | M31: 26861 | N31: 0.1607683 | O31: 1441477 | P31: 0 | Q31: 981170 | T31: #WebinarReplay | U31: 45479 | V31: =TEXT(U31,"DDDD") -> Saturday | W31: =TEXT(U31,"MMMM") -> July | X31: 11 | Y31: =IF(X31<6,"NIght",IF(X31<12,"Morning",IF(X31<18,"Afternoon","Evening"))) -> Morning | Z31: Medium
A32: Post_31 | B32: LinkedIn | C32: Organic | D32: Educational | E32: Image | F32: Australia | G32: 133.7751 | H32: -25.2744 | I32: 84944 | J32: 420660 | K32: 43112 | L32: 23390 | M32: 12224 | N32: 0.20193115 | O32: 517005 | P32: 0 | Q32: 0 | T32: #SuccessStory | U32: 45419 | V32: =TEXT(U32,"DDDD") -> Tuesday | W32: =TEXT(U32,"MMMM") -> May | X32: 15 | Y32: =IF(X32<6,"NIght",IF(X32<12,"Morning",IF(X32<18,"Afternoon","Evening"))) -> Afternoon | Z32: High
A33: Post_32 | B33: X.com | C33: Organic | D33: Product Promotion | E33: Video | F33: USA | G33: -95.7129 | H33: 37.0902 | I33: 230631 | J33: 2655192 | K33: 334965 | L33: 171384 | M33: 94178 | N33: 0.086860504 | O33: 3418150 | P33: 2655192 | Q33: 0 | T33: #ProductDemo | U33: 45649 | V33: =TEXT(U33,"DDDD") -> Monday | W33: =TEXT(U33,"MMMM") -> December | X33: 17 | Y33: =IF(X33<6,"NIght",IF(X33<12,"Morning",IF(X33<18,"Afternoon","Evening"))) -> Afternoon | Z33: Low
A34: Post_33 | B34: YouTube | C34: Organic | D34: Event / Webinar | E34: Live Stream | F34: USA | G34: -95.7129 | H34: 37.0902 | I34: 33791 | J34: 211173 | K34: 24711 | L34: 16098 | M34: 11634 | N34: 0.16001707 | O34: 243184 | P34: 0 | Q34: 1489976 | T34: #WebinarReplay | U34: 45407 | V34: =TEXT(U34,"DDDD") -> Thursday | W34: =TEXT(U34,"MMMM") -> April | X34: 10 | Y34: =IF(X34<6,"NIght",IF(X34<12,"Morning",IF(X34<18,"Afternoon","Evening"))) -> Morning | Z34: Medium
A35: Post_34 | B35: YouTube | C35: Organic | D35: Educational | E35: Video | F35: Australia | G35: 133.7751 | H35: -25.2744 | I35: 25047 | J35: 161448 | K35: 35935 | L35: 9325 | M35: 6649 | N35: 0.15514324 | O35: 185402 | P35: 143334 | Q35: 0 | T35: #CustomerStory | U35: 45306 | V35: =TEXT(U35,"DDDD") -> Monday | W35: =TEXT(U35,"MMMM") -> January | X35: 17 | Y35: =IF(X35<6,"NIght",IF(X35<12,"Morning",IF(X35<18,"Afternoon","Evening"))) -> Afternoon | Z35: Medium
A36: Post_35 | B36: YouTube | C36: Sponsored | D36: Educational | E36: Video | F36: UK | G36: -3.436 | H36: 55.3781 | I36: 49341 | J36: 275988 | K36: 41634 | L36: 13098 | M36: 13533 | N36: 0.17878045 | O36: 353105 | P36: 235164 | Q36: 0 | T36: #CustomerStory | U36: 45757 | V36: =TEXT(U36,"DDDD") -> Thursday | W36: =TEXT(U36,"MMMM") -> April | X36: 12 | Y36: =IF(X36<6,"NIght",IF(X36<12,"Morning",IF(X36<18,"Afternoon","Evening"))) -> Afternoon | Z36: Medium
A37: Post_36 | B37: TikTok | C37: Organic | D37: Educational | E37: Live Stream | F37: Japan | G37: 138.2529 | H37: 36.2048 | I37: 50766 | J37: 328182 | K37: 76487 | L37: 22642 | M37: 14991 | N37: 0.154689 | O37: 366522 | P37: 0 | Q37: 90407 | R37: 8136 | S37: 0.0222 | T37: #SuccessStory | U37: 45507 | V37: =TEXT(U37,"DDDD") -> Saturday | W37: =TEXT(U37,"MMMM") -> August | X37: 10 | Y37: =IF(X37<6,"NIght",IF(X37<12,"Morning",IF(X37<18,"Afternoon","Evening"))) -> Morning | Z37: Medium
A38: Post_37 | B38: LinkedIn | C38: Organic | D38: Educational | E38: Carousel | F38: Germany | G38: 10.4515 | H38: 51.1657 | I38: 49910 | J38: 272628 | K38: 27638 | L38: 9562 | M38: 12688 | N38: 0.18307075 | O38: 300166 | P38: 0 | Q38: 0 | T38: #SuccessStory | U38: 45457 | V38: =TEXT(U38,"DDDD") -> Friday | W38: =TEXT(U38,"MMMM") -> June | X38: 8 | Y38: =IF(X38<6,"NIght",IF(X38<12,"Morning",IF(X38<18,"Afternoon","Evening"))) -> Morning | Z38: Medium
A39: Post_38 | B39: Instagram | C39: Organic | D39: Product Promotion | E39: Video | F39: India | G39: 78.9629 | H39: 20.5937 | I39: 316200 | J39: 2635551 | K39: 327127 | L39: 151377 | M39: 125652 | N39: 0.11997522 | O39: 3242761 | P39: 2635551 | Q39: 0 | T39: #ProductDemo | U39: 45666 | V39: =TEXT(U39,"DDDD") -> Thursday | W39: =TEXT(U39,"MMMM") -> January | X39: 10 | Y39: =IF(X39<6,"NIght",IF(X39<12,"Morning",IF(X39<18,"Afternoon","Evening"))) -> Morning | Z39: Medium
A40: Post_39 | B40: TikTok | C40: Organic | D40: Product Promotion | E40: Video | F40: USA | G40: -95.7129 | H40: 37.0902 | I40: 310863 | J40: 2550875 | K40: 345866 | L40: 118028 | M40: 127185 | N40: 0.12186551 | O40: 3137388 | P40: 2550875 | Q40: 0 | R40: 33256 | S40: 0.0106 | T40: #ProductDemo | U40: 45311 | V40: =TEXT(U40,"DDDD") -> Saturday | W40: =TEXT(U40,"MMMM") -> January | X40: 11 | Y40: =IF(X40<6,"NIght",IF(X40<12,"Morning",IF(X40<18,"Afternoon","Evening"))) -> Morning | Z40: Medium
...

Sheet Clean_Data
A1: Post_ID | B1: Platform | C1: Content_Type | D1: Content_Category | E1: Post_Type | F1: Region | G1: Longitude | H1: Latitude | I1: Engagement | J1: Views | K1: Likes | L1: Shares | M1: Comments | N1: Engagement_Rate | O1: Impressions | P1: Video_Views | Q1: Live_Stream_Views | R1: Clicks | S1: Click_Through_Rate | T1: Main_Hashtag | U1: Post_Date | V1: Post_day | W1: Post_Month | X1: Post_Hour | Y1: Time_Slot | Z1: Engagement_Level
A2: Post_1 | B2: TikTok | C2: Organic | D2: Product Promotion | E2: Video | F2: UK | G2: -3.436 | H2: 55.3781 | I2: 54510 | J2: 599342 | K2: 125741 | L2: 35920 | M2: 15727 | N2: 0.09095057 | O2: 677975 | P2: 465645 | Q2: 0 | R2: 16813 | S2: 0.0248 | T2: #FeatureHighlight | U2: 45365 | V2: Thursday | W2: March | X2: 15 | Y2: Afternoon | Z2: Low
A3: Post_2 | B3: Instagram | C3: Organic | D3: Product Promotion | E3: Video | F3: India | G3: 78.9629 | H3: 20.5937 | I3: 259440 | J3: 1896301 | K3: 206151 | L3: 139015 | M3: 83521 | N3: 0.13681396 | O3: 2354474 | P3: 1896301 | Q3: 0 | T3: #ProductDemo | U3: 45406 | V3: Wednesday | W3: April | X3: 12 | Y3: Afternoon | Z3: Medium
A4: Post_3 | B4: X.com | C4: Organic | D4: Entertainment | E4: Text | F4: Brazil | G4: -51.9253 | H4: -14.235 | I4: 14182 | J4: 253052 | K4: 32206 | L4: 9912 | M4: 8140 | N4: 0.056045015 | O4: 304915 | P4: 0 | Q4: 0 | T4: #MemeMonday | U4: 45627 | V4: Sunday | W4: December | X4: 10 | Y4: Morning | Z4: Low
A5: Post_4 | B5: Instagram | C5: Organic | D5: Entertainment | E5: Carousel | F5: Australia | G5: 133.7751 | H5: -25.2744 | I5: 49137 | J5: 735640 | K5: 121227 | L5: 32781 | M5: 32716 | N5: 0.066795973 | O5: 829727 | P5: 0 | Q5: 0 | T5: #JustForFun | U5: 45480 | V5: Sunday | W5: July | X5: 12 | Y5: Afternoon | Z5: Low
A6: Post_5 | B6: TikTok | C6: Organic | D6: Educational | E6: Video | F6: Brazil | G6: -51.9253 | H6: -14.235 | I6: 20832 | J6: 77358 | K6: 13027 | L6: 5357 | M6: 2165 | N6: 0.26930187 | O6: 93049 | P6: 72707 | Q6: 0 | R6: 1944 | S6: 0.0209 | T6: #CaseStudy2025 | U6: 45301 | V6: Wednesday | W6: January | X6: 11 | Y6: Morning | Z6: High
A7: Post_6 | B7: LinkedIn | C7: Organic | D7: Customer Story | E7: Image | F7: Australia | G7: 133.7751 | H7: -25.2744 | I7: 47292 | J7: 217539 | K7: 41084 | L7: 7031 | M7: 9637 | N7: 0.21739867 | O7: 246712 | P7: 0 | Q7: 0 | T7: #SuccessStory | U7: 45327 | V7: Monday | W7: February | X7: 9 | Y7: Morning | Z7: High
A8: Post_7 | B8: YouTube | C8: Organic | D8: Customer Story | E8: Video | F8: Japan | G8: 138.2529 | H8: 36.2048 | I8: 44036 | J8: 189936 | K8: 38487 | L8: 9878 | M8: 4725 | N8: 0.23184858 | O8: 227739 | P8: 178450 | Q8: 0 | T8: #CustomerStory | U8: 45417 | V8: Sunday | W8: May | X8: 12 | Y8: Afternoon | Z8: High
A9: Post_8 | B9: YouTube | C9: Organic | D9: Customer Story | E9: Video | F9: UK | G9: -3.436 | H9: 55.3781 | I9: 325640 | J9: 1781229 | K9: 187310 | L9: 134422 | M9: 54062 | N9: 0.18281798 | O9: 2195372 | P9: 1781229 | Q9: 0 | T9: #CustomerStory | U9: 45374 | V9: Saturday | W9: March | X9: 15 | Y9: Afternoon | Z9: Medium
A10: Post_9 | B10: X.com | C10: Organic | D10: Product Promotion | E10: Text | F10: India | G10: 78.9629 | H10: 20.5937 | I10: 38084 | J10: 270886 | K10: 49303 | L10: 10630 | M10: 15923 | N10: 0.14059304 | O10: 339969 | P10: 0 | Q10: 0 | T10: #FeatureHighlight | U10: 45776 | V10: Tuesday | W10: April | X10: 16 | Y10: Afternoon | Z10: Medium
A11: Post_10 | B11: TikTok | C11: Organic | D11: Product Promotion | E11: Video | F11: India | G11: 78.9629 | H11: 20.5937 | I11: 76170 | J11: 530247 | K11: 124196 | L11: 31759 | M11: 30157 | N11: 0.14365078 | O11: 592656 | P11: 530247 | Q11: 0 | R11: 8949 | S11: 0.0151 | T11: #ProductDemo | U11: 45704 | V11: Sunday | W11: February | X11: 15 | Y11: Afternoon | Z11: Medium
A12: Post_11 | B12: Instagram | C12: Organic | D12: Event / Webinar | E12: Live Stream | F12: Germany | G12: 10.4515 | H12: 51.1657 | I12: 26520 | J12: 149091 | K12: 20977 | L12: 10650 | M12: 5109 | N12: 0.17788131 | O12: 172377 | P12: 0 | Q12: 317078 | T12: #EventRecap | U12: 45593 | V12: Monday | W12: October | X12: 10 | Y12: Morning | Z12: Medium
A13: Post_12 | B13: X.com | C13: Organic | D13: Educational | E13: Text | F13: Australia | G13: 133.7751 | H13: -25.2744 | I13: 22233 | J13: 91670 | K13: 11104 | L13: 6426 | M13: 2106 | N13: 0.24253383 | O13: 118930 | P13: 0 | Q13: 0 | T13: #SuccessStory | U13: 45405 | V13: Tuesday | W13: April | X13: 15 | Y13: Afternoon | Z13: High
A14: Post_13 | B14: YouTube | C14: Sponsored | D14: Educational | E14: Video | F14: Canada | G14: -106.3468 | H14: 56.1304 | I14: 226309 | J14: 1492308 | K14: 150466 | L14: 105615 | M14: 72040 | N14: 0.15165093 | O14: 1859119 | P14: 1492308 | Q14: 0 | T14: #CustomerStory | U14: 45695 | V14: Friday | W14: February | X14: 9 | Y14: Morning | Z14: Medium
A15: Post_14 | B15: YouTube | C15: Organic | D15: Educational | E15: Video | F15: Japan | G15: 138.2529 | H15: 36.2048 | I15: 71888 | J15: 311167 | K15: 67115 | L15: 10487 | M15: 10685 | N15: 0.23102875 | O15: 349494 | P15: 281653 | Q15: 0 | T15: #CustomerStory | U15: 45769 | V15: Tuesday | W15: April | X15: 19 | Y15: Evening | Z15: High
A16: Post_15 | B16: X.com | C16: Organic | D16: Entertainment | E16: Text | F16: Germany | G16: 10.4515 | H16: 51.1657 | I16: 53010 | J16: 566252 | K16: 84730 | L16: 18787 | M16: 18368 | N16: 0.093616415 | O16: 659704 | P16: 0 | Q16: 0 | T16: #FunContent | U16: 45428 | V16: Thursday | W16: May | X16: 15 | Y16: Afternoon | Z16: Low
A17: Post_16 | B17: YouTube | C17: Organic | D17: Product Promotion | E17: Live Stream | F17: Canada | G17: -106.3468 | H17: 56.1304 | I17: 30263 | J17: 347554 | K17: 72792 | L17: 21505 | M17: 19285 | N17: 0.087074837 | O17: 415133 | P17: 0 | Q17: 679391 | T17: #ProductDemo | U17: 45664 | V17: Tuesday | W17: January | X17: 15 | Y17: Afternoon | Z17: Low
A18: Post_17 | B18: X.com | C18: Organic | D18: Educational | E18: Image | F18: UK | G18: -3.436 | H18: 55.3781 | I18: 58337 | J18: 347296 | K18: 63968 | L18: 23806 | M18: 13805 | N18: 0.16797716 | O18: 418334 | P18: 0 | Q18: 0 | T18: #SuccessStory | U18: 45627 | V18: Sunday | W18: December | X18: 11 | Y18: Morning | Z18: Medium
A19: Post_18 | B19: TikTok | C19: Sponsored | D19: Educational | E19: Video | F19: UK | G19: -3.436 | H19: 55.3781 | I19: 510212 | J19: 2596696 | K19: 426198 | L19: 81201 | M19: 63140 | N19: 0.19648537 | O19: 2872688 | P19: 2596696 | Q19: 0 | R19: 31312 | S19: 0.0109 | T19: #CustomerStory | U19: 45454 | V19: Tuesday | W19: June | X19: 10 | Y19: Morning | Z19: Medium
A20: Post_19 | B20: TikTok | C20: Organic | D20: Product Promotion | E20: Video | F20: USA | G20: -95.7129 | H20: 37.0902 | I20: 29522 | J20: 216249 | K20: 38121 | L20: 16300 | M20: 6481 | N20: 0.13652218 | O20: 255622 | P20: 3466 | Q20: 0 | R20: 3246 | S20: 0.0127 | T20: #FeatureHighlight | U20: 45307 | V20: Tuesday | W20: January | X20: 11 | Y20: Morning | Z20: Medium
A21: Post_20 | B21: YouTube | C21: Organic | D21: Educational | E21: Video | F21: UK | G21: -3.436 | H21: 55.3781 | I21: 58869 | J21: 354249 | K21: 75572 | L21: 14680 | M21: 8175 | N21: 0.16618209 | O21: 410202 | P21: 308035 | Q21: 0 | T21: #CustomerStory | U21: 45579 | V21: Monday | W21: October | X21: 12 | Y21: Afternoon | Z21: Medium
A22: Post_21 | B22: X.com | C22: Organic | D22: Product Promotion | E22: Video | F22: Brazil | G22: -51.9253 | H22: -14.235 | I22: 340149 | J22: 2376086 | K22: 548208 | L22: 166762 | M22: 65253 | N22: 0.14315551 | O22: 3037853 | P22: 2376086 | Q22: 0 | T22: #ProductDemo | U22: 45460 | V22: Monday | W22: June | X22: 17 | Y22: Afternoon | Z22: Medium
A23: Post_22 | B23: TikTok | C23: Organic | D23: Product Promotion | E23: Live Stream | F23: USA | G23: -95.7129 | H23: 37.0902 | I23: 49757 | J23: 365818 | K23: 66176 | L23: 25743 | M23: 20428 | N23: 0.13601663 | O23: 425666 | P23: 0 | Q23: 77512 | R23: 4937 | S23: 0.0116 | T23: #FeatureHighlight | U23: 45683 | V23: Sunday | W23: January | X23: 15 | Y23: Afternoon | Z23: Medium
A24: Post_23 | B24: YouTube | C24: Organic | D24: Product Promotion | E24: Video | F24: Brazil | G24: -51.9253 | H24: -14.235 | I24: 197894 | J24: 1705918 | K24: 379911 | L24: 124594 | M24: 34592 | N24: 0.1160048 | O24: 2050768 | P24: 1705918 | Q24: 0 | T24: #ProductDemo | U24: 45610 | V24: Thursday | W24: November | X24: 19 | Y24: Evening | Z24: Medium
A25: Post_24 | B25: X.com | C25: Organic | D25: Product Promotion | E25: Video | F25: Japan | G25: 138.2529 | H25: 36.2048 | I25: 113610 | J25: 902363 | K25: 146734 | L25: 37091 | M25: 22373 | N25: 0.12590344 | O25: 1053529 | P25: 902363 | Q25: 0 | T25: #ProductDemo | U25: 45515 | V25: Sunday | W25: August | X25: 11 | Y25: Morning | Z25: Medium
A26: Post_25 | B26: YouTube | C26: Organic | D26: Educational | E26: Video | F26: Germany | G26: 10.4515 | H26: 51.1657 | I26: 58395 | J26: 233871 | K26: 41586 | L26: 15236 | M26: 8079 | N26: 0.24969113 | O26: 302712 | P26: 204799 | Q26: 0 | T26: #CustomerStory | U26: 45534 | V26: Friday | W26: August | X26: 12 | Y26: Afternoon | Z26: High
A27: Post_26 | B27: YouTube | C27: Organic | D27: Event / Webinar | E27: Live Stream | F27: Brazil | G27: -51.9253 | H27: -14.235 | I27: 42412 | J27: 290405 | K27: 70965 | L27: 12368 | M27: 11584 | N27: 0.14604667 | O27: 336920 | P27: 0 | Q27: 927260 | T27: #WebinarReplay | U27: 45434 | V27: Wednesday | W27: May | X27: 10 | Y27: Morning | Z27: Medium
A28: Post_27 | B28: Instagram | C28: Organic | D28: Product Promotion | E28: Video | F28: India | G28: 78.9629 | H28: 20.5937 | I28: 250854 | J28: 2076760 | K28: 364267 | L28: 67648 | M28: 64682 | N28: 0.12079132 | O28: 2661686 | P28: 2076760 | Q28: 0 | T28: #ProductDemo | U28: 45470 | V28: Thursday | W28: June | X28: 17 | Y28: Afternoon | Z28: Medium
A29: Post_28 | B29: YouTube | C29: Organic | D29: Entertainment | E29: Video | F29: Canada | G29: -106.3468 | H29: 56.1304 | I29: 35665 | J29: 413478 | K29: 56205 | L29: 15399 | M29: 16364 | N29: 0.086256793 | O29: 536334 | P29: 397501 | Q29: 0 | T29: #TrendingNow | U29: 45554 | V29: Thursday | W29: September | X29: 15 | Y29: Afternoon | Z29: Low
A30: Post_29 | B30: Instagram | C30: Organic | D30: Event / Webinar | E30: Live Stream | F30: Canada | G30: -106.3468 | H30: 56.1304 | I30: 35525 | J30: 326729 | K30: 69999 | L30: 13684 | M30: 16051 | N30: 0.10873047 | O30: 383434 | P30: 0 | Q30: 352922 | T30: #EventRecap | U30: 45674 | V30: Friday | W30: January | X30: 12 | Y30: Afternoon | Z30: Medium
A31: Post_30 | B31: YouTube | C31: Organic | D31: Event / Webinar | E31: Live Stream | F31: Japan | G31: 138.2529 | H31: 36.2048 | I31: 182898 | J31: 1137655 | K31: 221876 | L31: 64605 | M31: 26861 | N31: 0.1607683 | O31: 1441477 | P31: 0 | Q31: 981170 | T31: #WebinarReplay | U31: 45479 | V31: Saturday | W31: July | X31: 11 | Y31: Morning | Z31: Medium
A32: Post_31 | B32: LinkedIn | C32: Organic | D32: Educational | E32: Image | F32: Australia | G32: 133.7751 | H32: -25.2744 | I32: 84944 | J32: 420660 | K32: 43112 | L32: 23390 | M32: 12224 | N32: 0.20193115 | O32: 517005 | P32: 0 | Q32: 0 | T32: #SuccessStory | U32: 45419 | V32: Tuesday | W32: May | X32: 15 | Y32: Afternoon | Z32: High
A33: Post_32 | B33: X.com | C33: Organic | D33: Product Promotion | E33: Video | F33: USA | G33: -95.7129 | H33: 37.0902 | I33: 230631 | J33: 2655192 | K33: 334965 | L33: 171384 | M33: 94178 | N33: 0.086860504 | O33: 3418150 | P33: 2655192 | Q33: 0 | T33: #ProductDemo | U33: 45649 | V33: Monday | W33: December | X33: 17 | Y33: Afternoon | Z33: Low
A34: Post_33 | B34: YouTube | C34: Organic | D34: Event / Webinar | E34: Live Stream | F34: USA | G34: -95.7129 | H34: 37.0902 | I34: 33791 | J34: 211173 | K34: 24711 | L34: 16098 | M34: 11634 | N34: 0.16001707 | O34: 243184 | P34: 0 | Q34: 1489976 | T34: #WebinarReplay | U34: 45407 | V34: Thursday | W34: April | X34: 10 | Y34: Morning | Z34: Medium
A35: Post_34 | B35: YouTube | C35: Organic | D35: Educational | E35: Video | F35: Australia | G35: 133.7751 | H35: -25.2744 | I35: 25047 | J35: 161448 | K35: 35935 | L35: 9325 | M35: 6649 | N35: 0.15514324 | O35: 185402 | P35: 143334 | Q35: 0 | T35: #CustomerStory | U35: 45306 | V35: Monday | W35: January | X35: 17 | Y35: Afternoon | Z35: Medium
A36: Post_35 | B36: YouTube | C36: Sponsored | D36: Educational | E36: Video | F36: UK | G36: -3.436 | H36: 55.3781 | I36: 49341 | J36: 275988 | K36: 41634 | L36: 13098 | M36: 13533 | N36: 0.17878045 | O36: 353105 | P36: 235164 | Q36: 0 | T36: #CustomerStory | U36: 45757 | V36: Thursday | W36: April | X36: 12 | Y36: Afternoon | Z36: Medium
A37: Post_36 | B37: TikTok | C37: Organic | D37: Educational | E37: Live Stream | F37: Japan | G37: 138.2529 | H37: 36.2048 | I37: 50766 | J37: 328182 | K37: 76487 | L37: 22642 | M37: 14991 | N37: 0.154689 | O37: 366522 | P37: 0 | Q37: 90407 | R37: 8136 | S37: 0.0222 | T37: #SuccessStory | U37: 45507 | V37: Saturday | W37: August | X37: 10 | Y37: Morning | Z37: Medium
A38: Post_37 | B38: LinkedIn | C38: Organic | D38: Educational | E38: Carousel | F38: Germany | G38: 10.4515 | H38: 51.1657 | I38: 49910 | J38: 272628 | K38: 27638 | L38: 9562 | M38: 12688 | N38: 0.18307075 | O38: 300166 | P38: 0 | Q38: 0 | T38: #SuccessStory | U38: 45457 | V38: Friday | W38: June | X38: 8 | Y38: Morning | Z38: Medium
A39: Post_38 | B39: Instagram | C39: Organic | D39: Product Promotion | E39: Video | F39: India | G39: 78.9629 | H39: 20.5937 | I39: 316200 | J39: 2635551 | K39: 327127 | L39: 151377 | M39: 125652 | N39: 0.11997522 | O39: 3242761 | P39: 2635551 | Q39: 0 | T39: #ProductDemo | U39: 45666 | V39: Thursday | W39: January | X39: 10 | Y39: Morning | Z39: Medium
A40: Post_39 | B40: TikTok | C40: Organic | D40: Product Promotion | E40: Video | F40: USA | G40: -95.7129 | H40: 37.0902 | I40: 310863 | J40: 2550875 | K40: 345866 | L40: 118028 | M40: 127185 | N40: 0.12186551 | O40: 3137388 | P40: 2550875 | Q40: 0 | R40: 33256 | S40: 0.0106 | T40: #ProductDemo | U40: 45311 | V40: Saturday | W40: January | X40: 11 | Y40: Morning | Z40: Medium
...

Sheet Pivot_Table
A3: Count of Post_ID | B3: Column Labels
A4: Row Labels | B4: Organic | C4: Sponsored | D4: Grand Total
A5: Facebook | B5: 179 | C5: 120 | D5: 299
A6: LinkedIn | B6: 398 | C6: 127 | D6: 525
A7: Instagram | B7: 799 | C7: 199 | D7: 998
A8: X.com | B8: 1201 | D8: 1201
A9: TikTok | B9: 1009 | C9: 248 | D9: 1257
A10: YouTube | B10: 1060 | C10: 260 | D10: 1320
A11: Grand Total | B11: 4646 | C11: 954 | D11: 5600
A20: Row Labels | B20: Sum of Engagement
A21: Facebook | B21: 35701985
A22: LinkedIn | B22: 44731424
A23: X.com | B23: 133273396
A24: Instagram | B24: 134738386
A25: TikTok | B25: 146646344
A26: YouTube | B26: 151399907
A27: Grand Total | B27: 646491442
A36: Row Labels | B36: Sum of Views | C36: Sum of Likes | D36: Sum of Shares | E36: Sum of Comments
A37: Organic | B37: 3877399021 | C37: 680801489 | D37: 215493372 | E37: 156132873
A38: Sponsored | B38: 928876213 | C38: 163231875 | D38: 51542111 | E38: 37153783
A39: Grand Total | B39: 4806275234 | C39: 844033364 | D39: 267035483 | E39: 193286656
A52: Row Labels | B52: Sum of Impressions | C52: Sum of Engagement
A53: January | B53: 783793527 | C53: 87982973
A54: February | B54: 696997839 | C54: 79474496
A55: March | B55: 739299234 | C55: 81374858
A56: April | B56: 676760321 | C56: 75475660
A57: May | B57: 355303098 | C57: 39516388
A58: June | B58: 381348633 | C58: 41542295
A59: July | B59: 354247418 | C59: 39627858
A60: August | B60: 379483732 | C60: 39639195
A61: September | B61: 314212992 | C61: 36838691
A62: October | B62: 363696114 | C62: 43118643
A63: November | B63: 348522834 | C63: 39813792
A64: December | B64: 372890002 | C64: 42086593
A65: Grand Total | B65: 5766555744 | C65: 646491442
A71: Row Labels | B71: Sum of Engagement
A72: Article | B72: 25415618
A73: Carousel | B73: 5666210
A74: Image | B74: 58601693
A75: Live Stream | B75: 52172995
...

Sheet Dashboard
O50: Social Media Analyssis Report
G53: Total Post | H53: =Pivot_Table!A109 -> 5600 | I53: Total Shares | K53: =Pivot_Table!C109 -> 267035483 | L53: Total Views | N53: =Pivot_Table!B109 -> 4806275234 | O53: Total Likes | Q53: =Pivot_Table!E109+Pivot_Table!E109 -> 1688066728 | R53: Total Comments | T53: =Pivot_Table!D109 -> 193286656 | U53: Total Engagements | W53: =Pivot_Table!F109 -> 646491442 | X53: Total Impressions | Z53: =Pivot_Table!G109 -> 5766555744
